Workbook

Sheet Menu Item Price vs POS Price
A1: ITEM NAME | B1: ITEM PRICE | C1: POS PRICE | D1: AFTER TAX PRICE | E1: PROFIT MARGIN
A2: BIG BREAKFAST W/BACON | B2: ='Menu item calculator'!F12 -> 15.227749 | C2: 33 | D2: =C2+(C2*6%)+(C2*10%) -> 38.28 | E2: =(C2-B2)/C2 -> 0.53855307
A3: BIG BREAKFAST W/CHICKEN | B3: ='Menu item calculator'!F26 -> 15.227749 | C3: 33 | D3: =C3+(C3*6%)+(C3*10%) -> 38.28 | E3: =(C3-B3)/C3 -> 0.53855307
A4: BIG BREAKFAST W/PORK | B4: ='Menu item calculator'!F40 -> 15.227749 | C4: 33 | D4: =C4+(C4*6%)+(C4*10%) -> 38.28 | E4: =(C4-B4)/C4 -> 0.53855307
A5: BIG BREAKFAST W/BEEF | B5: ='Menu item calculator'!F54 -> 15.619249 | C5: 33 | D5: =C5+(C5*6%)+(C5*10%) -> 38.28 | E5: =(C5-B5)/C5 -> 0.52668943
A6: ALL DAY W/BACON | B6: ='Menu item calculator'!F68 -> 12.302455 | C6: 32 | D6: =C6+(C6*6%)+(C6*10%) -> 37.12 | E6: =(C6-B6)/C6 -> 0.61554828
A7: ALL DAY W/CHICKEN | B7: ='Menu item calculator'!F82 -> 12.302455 | C7: 32 | D7: =C7+(C7*6%)+(C7*10%) -> 37.12 | E7: =(C7-B7)/C7 -> 0.61554828
A8: ALL DAY W/PORK | B8: ='Menu item calculator'!F96 -> 12.302455 | C8: 32 | D8: =C8+(C8*6%)+(C8*10%) -> 37.12 | E8: =(C8-B8)/C8 -> 0.61554828
A9: ALL DAY W/BEEF | B9: ='Menu item calculator'!F110 -> 12.693955 | C9: 32 | D9: =C9+(C9*6%)+(C9*10%) -> 37.12 | E9: =(C9-B9)/C9 -> 0.6033139
A10: CREPPES W/CARAMELIZED BANANA | B10: ='Menu item calculator'!F121 -> 3.7039399 | C10: 24 | D10: =C10+(C10*6%)+(C10*10%) -> 27.84 | E10: =(C10-B10)/C10 -> 0.84566917
A11: CREPPES W/LEMON & SUGAR | B11: ='Menu item calculator'!F133 -> 2.8514399 | C11: 24 | D11: =C11+(C11*6%)+(C11*10%) -> 27.84 | E11: =(C11-B11)/C11 -> 0.88119
A12: CREPPES W/NUTELLA | B12: ='Menu item calculator'!F144 -> 4.2102046 | C12: 24 | D12: =C12+(C12*6%)+(C12*10%) -> 27.84 | E12: =(C12-B12)/C12 -> 0.82457481
A13: OMELETTE PLAIN | B13: ='Menu item calculator'!F156 -> 6.0332661 | C13: 28 | D13: =C13+(C13*6%)+(C13*10%) -> 32.48 | E13: =(C13-B13)/C13 -> 0.78452621
A14: OMELETTE W/SALMON 50GM | B14: ='Menu item calculator'!F169 -> 12.433266 | C14: 32 | D14: =C14+(C14*6%)+(C14*10%) -> 37.12 | E14: =(C14-B14)/C14 -> 0.61146043
A15: OMELETTE W/CHEESE & MUSHROOM | B15: ='Menu item calculator'!F183 -> 8.7232661 | C15: 28 | D15: =C15+(C15*6%)+(C15*10%) -> 32.48 | E15: =(C15-B15)/C15 -> 0.68845478
A16: EGGS BENEDICT W/BACON | B16: ='Menu item calculator'!F197 -> 10.626496 | C16: 33 | D16: =C16+(C16*6%)+(C16*10%) -> 38.28 | E16: =(C16-B16)/C16 -> 0.67798497
A17: EGGS MARLBOROUGH W/SALMON | B17: ='Menu item calculator'!F211 -> 13.598996 | C17: 33 | D17: =C17+(C17*6%)+(C17*10%) -> 38.28 | E17: =(C17-B17)/C17 -> 0.58790921
A18: TOAST W/BUTTER & JAM | B18: ='Menu item calculator'!F220 -> 0.28246867 | C18: 13 | D18: =C18+(C18*6%)+(C18*10%) -> 15.08 | E18: =(C18-B18)/C18 -> 0.97827164
A19: SWEET CORN PANCAKES W/BACON | B19: RECIPE MISSING | C19: 29 | D19: =C19+(C19*6%)+(C19*10%) -> 33.64 | E19: =(C19-B19)/C19 -> #VALUE!
A20: MUESLI W/HONEY,YOGHURT,FRUIT | B20: ='Menu item calculator'!F245 -> 4.7135225 | C20: 25 | D20: =C20+(C20*6%)+(C20*10%) -> 29 | E20: =(C20-B20)/C20 -> 0.8114591
A21: PANCAKE BANANA | B21: ='Menu item calculator'!F255 -> 6.893627 | C21: 28 | D21: =C21+(C21*6%)+(C21*10%) -> 32.48 | E21: =(C21-B21)/C21 -> 0.75379904
A22: PORRIDGE W/HONEY & BANANA | B22: ='Menu item calculator'!F268 -> 3.5439749 | C22: 20 | D22: =C22+(C22*6%)+(C22*10%) -> 23.2 | E22: =(C22-B22)/C22 -> 0.82280126
A23: ASPARAGUS W/BACON | B23: ='Menu item calculator'!F279 -> 11.724653 | C23: 28 | D23: =C23+(C23*6%)+(C23*10%) -> 32.48 | E23: =(C23-B23)/C23 -> 0.5812624
A24: SCRAMBLED EGGS W/SALMON 50G | B24: ='Menu item calculator'!F291 -> 12.345573 | C24: 32 | D24: =C24+(C24*6%)+(C24*10%) -> 37.12 | E24: =(C24-B24)/C24 -> 0.61420085
A25: FRESH FRUIT SALAD W/YOGHURT | B25: ='Menu item calculator'!F298 -> 2.9467 | C25: 20 | D25: =C25+(C25*6%)+(C25*10%) -> 23.2 | E25: =(C25-B25)/C25 -> 0.852665
A26: FRENCH TOAST W/BERRY COMPOTE | B26: ='Menu item calculator'!F309 -> 5.3527634 | C26: 28 | D26: =C26+(C26*6%)+(C26*10%) -> 32.48 | E26: =(C26-B26)/C26 -> 0.80882988
A27: FRENCH TOAST W/BANANA BACON | B27: ='Menu item calculator'!F320 -> 5.8647389 | C27: 30 | D27: =C27+(C27*6%)+(C27*10%) -> 34.8 | E27: =(C27-B27)/C27 -> 0.8045087
A28: FRENCH TOAST W/BACON & MAPLE | B28: ='Menu item calculator'!F331 -> 5.7092389 | C28: 30 | D28: =C28+(C28*6%)+(C28*10%) -> 34.8 | E28: =(C28-B28)/C28 -> 0.80969204
A29: FRENCH TOAST W/PEARS & BACON | B29: 7.8397811 | C29: 26 | D29: =C29+(C29*6%)+(C29*10%) -> 30.16 | E29: =(C29-B29)/C29 -> 0.69846996
A30: TOMATO W/ MUSHROOM ON TOAST | B30: ='Menu item calculator'!F360 -> 6.7422917 | C30: 29 | D30: =C30+(C30*6%)+(C30*10%) -> 33.64 | E30: =(C30-B30)/C30 -> 0.76750718
A31: BACON & EGG PIE | B31: ='Menu item calculator'!F378 -> 10.595723 | C31: 30 | D31: =C31+(C31*6%)+(C31*10%) -> 34.8 | E31: =(C31-B31)/C31 -> 0.64680924
A32: SCRAMBLED EGGS FETA W/SPINACH | B32: ='Menu item calculator'!F389 -> 6.4831278 | C32: 28 | D32: =C32+(C32*6%)+(C32*10%) -> 32.48 | E32: =(C32-B32)/C32 -> 0.76845972
A33: AVOCADO BACON ON TOAST | B33: ='Menu item calculator'!F402 -> 3.4825109 | C33: 33 | D33: =C33+(C33*6%)+(C33*10%) -> 38.28 | E33: =(C33-B33)/C33 -> 0.89446937
A34: AVOCADO HALOUMI CHEES ON TOAST | B34: ='Menu item calculator'!F415 -> 7.4961841 | C34: 33 | D34: =C34+(C34*6%)+(C34*10%) -> 38.28 | E34: =(C34-B34)/C34 -> 0.77284291
A35: AVOCADO ON TOAST W/ SALMON | B35: ='Menu item calculator'!F430 -> 8.1066261 | C35: 33 | D35: =C35+(C35*6%)+(C35*10%) -> 38.28 | E35: =(C35-B35)/C35 -> 0.75434467
A36: NASI GORENG | B36: ='Menu item calculator'!F447 -> 5.6296128 | C36: 34 | D36: =C36+(C36*6%)+(C36*10%) -> 39.44 | E36: =(C36-B36)/C36 -> 0.83442315
A37: OPEN BACON ROCKET SANDWICH | B37: ='Menu item calculator'!F459 -> 6.5508333 | C37: 28 | D37: =C37+(C37*6%)+(C37*10%) -> 32.48 | E37: =(C37-B37)/C37 -> 0.76604167
A38: OPEN BACON LETTUCE SANDWICH | B38: ='Menu item calculator'!F471 -> 6.0708333 | C38: 28 | D38: =C38+(C38*6%)+(C38*10%) -> 32.48 | E38: =(C38-B38)/C38 -> 0.78318452
A39: OPEN CHICKEN SANDWICH | B39: ='Menu item calculator'!F483 -> 3.6417156 | C39: 28 | D39: =C39+(C39*6%)+(C39*10%) -> 32.48 | E39: =(C39-B39)/C39 -> 0.86993873
A40: THAI CHICKEN SATAY | B40: ='Menu item calculator'!F494 -> 4.7674818 | C40: 26 | D40: =C40+(C40*6%)+(C40*10%) -> 30.16 | E40: =(C40-B40)/C40 -> 0.81663532
...

Sheet Master Price list
A1: SUPPLIER NAME | B1: OUTLET ITEM CODE | C1: ITEM DESCRIPTION | D1: SUPPLIER UOM | E1: CONVERTED UOM | F1: SUPPLIER PRICE | G1: CONVERTED PRICE
A2: LEE'S FROZEN SDN BHD | B2: MT-01 | C2: BEEF STRIPLOIN (BURGER) | D2: KG | E2: KG | F2: 56 | G2: 56
A3: LEE'S FROZEN SDN BHD | B3: MT-02 | C3: BEEF TENDERLOIN (KEBAB/SALAD/NOODLE) | D3: KG | E3: KG | F3: 100 | G3: 100
A4: NEW CUISINEFINE FOODS SDN BHD | B4: MT-03 | C4: LAMB LEG (KEBAB/BURGER) | D4: KG | E4: KG | F4: 71 | G4: 71
A5: NEW CUISINEFINE FOODS SDN BHD | B5: MT-04 | C5: MINCED BEEF | D5: KG | E5: KG | F5: 40 | G5: 40
A6: NEW CUISINEFINE FOODS SDN BHD | B6: MT-05 | C6: MINCED LAMB | D6: KG | E6: KG | F6: 56.5 | G6: 56.5
A7: ORIENTS FRESH DELI SDN BHD | B7: MT-06 | C7: BACK BACON, SLICED | D7: KG | E7: KG | F7: 45.7 | G7: 45.7
A8: ORIENTS FRESH DELI SDN BHD | B8: MT-07 | C8: STREAKY BACON, SLICED | D8: KG | E8: KG | F8: 47 | G8: 39.38
A9: EURO DELI MANUFACTURING SDN BHD | B9: MT-08 | C9: BEEF SAUSAGE | D9: KG | E9: KG | F9: 50.92 | G9: 50.92
A10: EURO DELI MANUFACTURING SDN BHD | B10: MT-09 | C10: CHORIZO SAUSAGE | D10: KG | E10: KG | F10: 42.94 | G10: 42.94
A11: EURO DELI MANUFACTURING SDN BHD | B11: MT-10 | C11: PORK SAUSAGE, BANGER | D11: KG | E11: KG | F11: 45.7 | G11: 45.7
A12: HANKEE PROCESSING SDN BHD | B12: PT-01 | C12: CHICKEN FILLET | D12: CTN / 6PKT/ 2KG | E12: KG | F12: 18 | G12: =F12/2 -> 9
A13: HANKEE PROCESSING SDN BHD | B13: PT-02 | C13: CHICKEN BREAST, WITH SKIN | D13: CTN / 6PKT/ 2KG | E13: KG | F13: 20.6 | G13: =F13/2 -> 10.3
A14: EURO DELI MANUFACTURING SDN BHD | B14: PT-04 | C14: CHICKEN SAUSAGE, BLACK PEPPER | D14: KG | E14: KG | F14: 45.7 | G14: 45.7
A15: ORIENTS FRESH DELI SDN BHD | B15: PT-05 | C15: SMOKED CHICKEN | D15: KG | E15: KG | F15: 26.57 | G15: 26.57
A16: NEW CUISINEFINE FOODS SDN BHD | B16: FISH-01 | C16: SALMON FILLET, NORWAY | D16: KG | E16: KG | F16: 80 | G16: 80
A17: NEW CUISINEFINE FOODS SDN BHD | B17: FISH-02 | C17: SMOKED SALMON FILLET, PRESLICED, FROZEN (NOR) | D17: KG | E17: KG | F17: 128 | G17: 128
A18: ALBATROSS EXIM (M) SDN BHD | B18: FISH-03 | C18: HOKI FILLET | D18: KG | E18: KG | F18: 41 | G18: 41
A19: NEW CUISINEFINE FOODS SDN BHD | B19: FISH-04 | C19: DORY FILLET | D19: PKT / 750GM | E19: KG | F19: 43.9 | G19: =F19/750*1000 -> 58.533333
A20: GLOBAL-PACIFIC VICTORY (M) SDN BHD | B20: DR-01 | C20: BUFFALO MOZZARELLA CHEESE | D20: PKT / 125GM | E20: PKT | F20: 15 | G20: 15
A21: NEW CUISINE FINEFOODS SDN BHD | B21: DR-02 | C21: BUTTER, SALTED | D21: CTN / 25KG | E21: KG | F21: 980 | G21: =F21/25 -> 39.2
A22: NEW CUISINE FINEFOODS SDN BHD | B22: DR-03 | C22: CREAME CHEESE | D22: BLOCK / 1.8KG | E22: KG | F22: 68.2 | G22: =F22/1800*1000 -> 37.888889
A23: GLOBAL-PACIFIC VICTORY (M) SDN BHD | B23: DR-04 | C23: CAMEMBERT CHEESE | D23: PKT / 125GM | E23: KG | F23: 16.5 | G23: =F23/125*1000 -> 132
A24: NEW CUISINE FINEFOODS SDN BHD | B24: DR-05 | C24: CHEDDAR CHEESE, SHREDDED | D24: PKT / 2KG | E24: KG | F24: 100 | G24: =F24/2 -> 50
A25: PASTRY PRO SDN BHD | B25: DR-06 | C25: CHOCOLATE CHIPS, COMPOUND DARK | D25: PKT / 5KG | E25: KG | F25: 17.9 | G25: =F25/5 -> 3.58
A26: PASTRY PRO SDN BHD | B26: DR-07 | C26: DARK BITTER SWEET CHOCOLATE, 60% | D26: PKT / 1KG | E26: KG | F26: 50.8 | G26: 50.8
A27: BIDFOOD MALAYSIA SDN BHD | B27: DR-08 | C27: FARMHOUSE COFFEE MILK | D27: CTN / 12 PKT | E27: KG | F27: 108 | G27: =F27/12 -> 9
A28: BIDFOOD MALAYSIA SDN BHD | B28: DR-09 | C28: FARMHOUSE LOW FAT MILK | D28: CTN / 12 PKT | E28: KG | G28: =F28/12 -> 0
A29: NEW CUISINE FINEFOODS SDN BHD | B29: DR-10 | C29: FETA CHEESE | D29: CTN / 6TUB / 200GM | E29: KG | F29: 17 | G29: =F29/200*1000 -> 85
A30: GLOBAL-PACIFIC VICTORY (M) SDN BHD | B30: DR-11 | C30: HALOUMI CHEESE | D30: PKT / 180GM | E30: KG | F30: 26 | G30: =F30/180*1000 -> 144.44444
A31: GLOBAL-PACIFIC VICTORY (M) SDN BHD | B31: DR-12 | C31: MASCARPONE CHEESE | D31: PKT / 1KG | E31: KG | F31: 38.1 | G31: 38.1
A32: NEW CUISINE FINEFOODS SDN BHD | B32: DR-14 | C32: MOZZARELLA CHEESE, SHREDDED | D32: PKT / 2KG | E32: KG | F32: 81.5 | G32: =F32/2 -> 40.75
A33: GLOBAL-PACIFIC VICTORY (M) SDN BHD | B33: DR-15 | C33: PARMESAN CHEESE, PARMIGIANO REGIANO | D33: KG | E33: KG | F33: 95 | G33: 95
A34: GLOBAL-PACIFIC VICTORY (M) SDN BHD | B34: DR-16 | C34: SOUR CREAM | D34: PKT / 1KG | E34: KG | F34: 20.5 | G34: 20.5
A35: NEW CUISINE FINEFOODS SDN BHD | B35: DR-17 | C35: YOGURT | D35: TUB / 1KG | E35: KG | F35: 29 | G35: 29
A36: GLOBAL-PACIFIC VICTORY (M) SDN BHD | B36: DR-18 | C36: WHIPPING CREAM 38% | D36: PKT / 1LITRE | E36: KG | F36: 22 | G36: 22
A37: GLOBAL-PACIFIC VICTORY (M) SDN BHD | B37: DR-19 | C37: WHIPPING CREAM (AEROSOL) | D37: TIN / 400GM | E37: KG | F37: 22 | G37: =F37/400*1000 -> 55
A38: PASTRY PRO SDN BHD | B38: DR-20 | C38: WHITE CHOCOLATE CHIPS 35% | D38: PKT / 1KG | E38: KG | F38: 67.3 | G38: 67.3
A39: FRESHMEN MARKETING SDN BHD | B39: SS-01 | C39: BAY LEAF, DRIED | D39: PKT / 1KG | E39: KG | F39: 15 | G39: 15
A40: FRESHMEN MARKETING SDN BHD | B40: SS-02 | C40: BLACK PEPPERCORN | D40: PKT / 1KG | E40: KG | F40: 48 | G40: 48
...

Sheet Item list
A1: ITEM NAME | B1: ITEM PRICE | C1: UOM
A2: SCRAMBLED EGGS | B2: ='Item list calculator'!I10 -> 3.6284444 | C2: SERVING
A3: SAUTEED MUSHROOMS | B3: ='Item list calculator'!I23 -> 4.1504444 | C3: SERVING
A4: FRUIT SALAD | B4: ='Item list calculator'!I39 -> 2.9467 | C4: SERVING
A5: BALANA PANCAKE BATTER | B5: ='Item list calculator'!I59 -> 5.4060667 | C5: SERVING
A6: FRENCH TOAST BATTER | B6: ='Item list calculator'!I74 -> 0.67908889 | C6: SERVING
A7: WAFFLE BATTER | B7: ='Item list calculator'!I89 -> 2.3327444 | C7: SERVING
A8: CREPE BATTER | B8: ='Item list calculator'!I102 -> 2.1545599 | C8: SERVING
A9: FISH & CHIPS BATTER | B9: ='Item list calculator'!I115 -> 2.0643378 | C9: SERVING
A10: TOMATO BAGEL | B10: ='Item list calculator'!I132 -> 2.0792454 | C10: PIECE
A11: WHAKATIKI BATTER | B11: ='Item list calculator'!I144 -> 0.94003529 | C11: SERVING
A12: PUMPKIN SOUP | B12: ='Item list calculator'!I158 -> 0.99315278 | C12: SERVING
A13: RED SOUP | B13: ='Item list calculator'!I175 -> 1.1553965 | C13: SERVING
A14: LAMB KEBAB | B14: ='Item list calculator'!I193 -> 15.347866 | C14: SERVING
A15: BEEF KEBAB | B15: ='Item list calculator'!I212 -> 20.63527 | C15: SERVING
A16: GRILLED CHICKEN | B16: ='Item list calculator'!I247 -> 2.0735289 | C16: SERVING
A17: CHICKEN SATAY | B17: ='Item list calculator'!I235 -> 1.9025
A18: SWEET PAPRIKA CHICKEN | B18: ='Item list calculator'!I262 -> 2.8409889 | C18: SERVING
A19: CHICKEN KEBAB | B19: ='Item list calculator'!I282 -> 3.7496444 | C19: SERVING
A20: PIZZA SAUCE | B20: ='Item list calculator'!I299 -> 16.610233 | C20: KG
A21: SALAD DRESSING | B21: ='Item list calculator'!I310 -> 35.2475 | C21: KG
A22: PIZZA DOUGH | B22: ='Item list calculator'!I324 -> 1.2713037 | C22: PIECE
A23: PASTA TOMATO SAUCE | B23: ='Item list calculator'!I338 -> 34.446361 | C23: KG
A24: DOUBLE SALMON FISHCAKE | B24: ='Item list calculator'!I352 -> 4.572451 | C24: SERVING
A25: LAMB BURGER | B25: ='Item list calculator'!I366 -> 9.2651785 | C25: SERVING
A26: BEEF BURGER | B26: ='Item list calculator'!I383 -> 6.0969335 | C26: SERVING
A27: MUESLI | B27: ='Item list calculator'!I394 -> 28.88225 | C27: KG
A28: MEATBALLS | B28: ='Item list calculator'!I408 -> 5.9709 | C28: SERVING
A29: OMELETTE | B29: ='Item list calculator'!I417 -> 7.4593889 | C29: SERVING
A30: HASHBROWN | B30: ='Item list calculator'!I430 -> 1.7707397 | C30: PIECE
A31: HOUSE SALAD | B31: ='Item list calculator'!I442 -> 1.7691118 | C31: SERVING
A32: BEETROOT SALAD | B32: ='Item list calculator'!I456 -> 3.5986875 | C32: SERVING
A33: NUT MIX | B33: ='Item list calculator'!I472 -> 25.96125 | C33: KG
A34: CHICK PEA SALAD | B34: ='Item list calculator'!I486 -> 14.069831 | C34: KG
A35: ROASTED VEGGIE | B35: ='Item list calculator'!I500 -> 1.9002143 | C35: SERVING
A36: AVOCADO SPREAD | B36: ='Item list calculator'!I513 -> 5.5563542 | C36: KG
A37: CHEESE HOLLANDAISE | B37: ='Item list calculator'!I526 -> 48.182254 | C37: KG
A38: TOMATO PESTO | B38: ='Item list calculator'!I540 -> 46.530917 | C38: KG
A39: TARTAR SAUCE | B39: ='Item list calculator'!I555 -> 15.453278 | C39: KG
A40: TZATZIKI SAUCE | B40: ='Item list calculator'!I567 -> 20.794 | C40: KG
...

Sheet Item list calculator
A1: SCRAMBLED EGG | G1: PORTIONS PER RECIPE | I1: 1
A2: NO | B2: INGREDIENT | C2: QUANTITY | D2: UOM | E2: UNIT PRICE | F2: TOTAL | G2: YIELD LOSS (%) | H2: YIELD LOSS VALUE | I2: GRAND TOTAL
A4: 1 | B4: EGG | C4: 2 | D4: PCS | E4: ='Master Price list'!G207 -> 0.5 | F4: =E4*C4 -> 1 | G4: 0 | H4: =F4/100*G4 -> 0 | I4: =H4+F4 -> 1
A5: 2 | B5: WHIPPING CREAM | C5: 0.09 | D5: KG | E5: ='Master Price list'!G36 -> 22 | F5: =E5*C5 -> 1.98 | G5: 0 | H5: =F5/100*G5 -> 0 | I5: =H5+F5 -> 1.98
A6: 3 | B6: SALT | C6: 0.001 | D6: KG | E6: ='Master Price list'!G62 -> 4.4444444 | F6: =E6*C6 -> 0.0044444444 | G6: 0 | H6: =F6/100*G6 -> 0 | I6: =H6+F6 -> 0.0044444444
A7: 4 | B7: BLACK PEPPER, FINE COURSE | C7: 0.001 | D7: KG | E7: ='Master Price list'!G41 -> 56 | F7: =E7*C7 -> 0.056 | G7: 0 | H7: =F7/100*G7 -> 0 | I7: =H7+F7 -> 0.056
A8: 5 | B8: BUTTER. SALTED | C8: 0.015 | D8: KG | E8: ='Master Price list'!G21 -> 39.2 | F8: =E8*C8 -> 0.588 | G8: 0 | H8: =F8/100*G8 -> 0 | I8: =H8+F8 -> 0.588
G9: TOTAL | I9: =SUM(I4:I8) -> 3.6284444
G10: PRICE PER UNIT | I10: =I9/I1 -> 3.6284444
A13: SAUTEED MUSHROOMS | G13: PORTIONS PER RECIPE | I13: 1
A14: NO | B14: INGREDIENT | C14: QUANTITY | D14: UOM | E14: UNIT PRICE | F14: TOTAL | G14: YIELD LOSS (%) | H14: YIELD LOSS VALUE | I14: GRAND TOTAL
A16: 1 | B16: MUSHROOMS | C16: 0.12 | D16: KG | E16: ='Master Price list'!G182 -> 23.8 | F16: =E16*C16 -> 2.856 | G16: 0 | H16: =F16/100*G16 -> 0 | I16: =H16+F16 -> 2.856
A17: 2 | B17: BUTTER. SALTED | C17: 0.015 | D17: KG | E17: ='Master Price list'!G21 -> 39.2 | F17: =E17*C17 -> 0.588 | G17: 0 | H17: =F17/100*G17 -> 0 | I17: =H17+F17 -> 0.588
A18: 3 | B18: CODIANDER | C18: 0.002 | D18: KG | E18: ='Master Price list'!G174 -> 15 | F18: =E18*C18 -> 0.03 | G18: 20 | H18: =F18/100*G18 -> 0.006 | I18: =H18+F18 -> 0.036
A19: 4 | B19: PARSLEY | C19: 0.002 | D19: KG | E19: ='Master Price list'!G191 -> 15 | F19: =E19*C19 -> 0.03 | G19: 20 | H19: =F19/100*G19 -> 0.006 | I19: =H19+F19 -> 0.036
A20: 5 | B20: SALT | C20: 0.001 | D20: KG | E20: ='Master Price list'!G62 -> 4.4444444 | F20: =E20*C20 -> 0.0044444444 | G20: 0 | H20: =F20/100*G20 -> 0 | I20: =H20+F20 -> 0.0044444444
A21: 6 | B21: OLIVE OIL | C21: 0.015 | D21: KG | E21: ='Master Price list'!G80 -> 42 | F21: =E21*C21 -> 0.63 | G21: 0 | H21: =F21/100*G21 -> 0 | I21: =H21+F21 -> 0.63
G22: TOTAL | I22: =SUM(I16:I21) -> 4.1504444
G23: PRICE PER UNIT (SERVING) | I23: =I22/I13 -> 4.1504444
A26: FRUIT SALAD | G26: PORTIONS PER RECIPE | I26: 1
A27: NO | B27: INGREDIENT | C27: QUANTITY | D27: UOM | E27: UNIT PRICE | F27: TOTAL | G27: YIELD LOSS (%) | H27: YIELD LOSS VALUE | I27: GRAND TOTAL
A29: 1 | B29: BANANA | C29: 0.05 | D29: KG | E29: ='Master Price list'!G158 -> 5.3 | F29: =E29*C29 -> 0.265 | G29: 0 | H29: =F29/100*G29 -> 0 | I29: =H29+F29 -> 0.265
A30: 2 | B30: PINEAPPLE | C30: 0.05 | D30: KG | E30: ='Master Price list'!G220 -> 6.3 | F30: =E30*C30 -> 0.315 | G30: 10 | H30: =F30/100*G30 -> 0.0315 | I30: =H30+F30 -> 0.3465
A31: 3 | B31: MELON | C31: 0.05 | D31: KG | E31: ='Master Price list'!G216 -> 7 | F31: =E31*C31 -> 0.35 | G31: 10 | H31: =F31/100*G31 -> 0.035 | I31: =H31+F31 -> 0.385
A32: 4 | B32: WATERMELON | C32: 0.05 | D32: KG | E32: ='Master Price list'!G221 -> 3.8 | F32: =E32*C32 -> 0.19 | G32: 10 | H32: =F32/100*G32 -> 0.019 | I32: =H32+F32 -> 0.209
A33: 5 | B33: LEMON JUICE | C33: 0.008 | D33: KG | E33: ='Master Price list'!G222 -> 37.8 | F33: =E33*C33 -> 0.3024 | G33: 0 | H33: =F33/100*G33 -> 0 | I33: =H33+F33 -> 0.3024
A34: 6 | B34: BASIL LEAF | C34: 0.001 | D34: KG | E34: ='Master Price list'!G160 -> 86 | F34: =E34*C34 -> 0.086 | G34: 0 | H34: =F34/100*G34 -> 0 | I34: =H34+F34 -> 0.086
A35: 7 | B35: MINT LEAF | C35: 0.001 | D35: KG | E35: ='Master Price list'!G187 -> 8.8 | F35: =E35*C35 -> 0.0088 | G35: 0 | H35: =F35/100*G35 -> 0 | I35: =H35+F35 -> 0.0088
A36: 8 | B36: YOGURT | C36: 0.03 | D36: KG | E36: ='Master Price list'!G35 -> 29 | F36: =E36*C36 -> 0.87 | G36: 0 | H36: =F36/100*G36 -> 0 | I36: =H36+F36 -> 0.87
A37: 9 | B37: HONEY | C37: 0.03 | D37: KG | E37: ='Master Price list'!G146 -> 15.8 | F37: =E37*C37 -> 0.474 | G37: 0 | H37: =F37/100*G37 -> 0 | I37: =H37+F37 -> 0.474
G38: TOTAL | I38: =SUM(I29:I37) -> 2.9467
G39: PRICE PER UNIT (SERVING) | I39: =I38/I26 -> 2.9467
A43: BANANA PANCAKE | G43: PORTIONS PER RECIPE | I43: 2
A44: NO | B44: INGREDIENT | C44: QUANTITY | D44: UOM | E44: UNIT PRICE | F44: TOTAL | G44: YIELD LOSS (%) | H44: YIELD LOSS VALUE | I44: GRAND TOTAL
A46: 1 | B46: BANANA | C46: 0.1 | D46: KG | E46: ='Master Price list'!G158 -> 5.3 | F46: =E46*C46 -> 0.53 | G46: 20 | H46: =F46/100*G46 -> 0.106 | I46: =H46+F46 -> 0.636
A47: 2 | B47: MILK | C47: 0.16 | D47: KG | E47: ='Master Price list'!G27 -> 9 | F47: =E47*C47 -> 1.44 | G47: 0 | H47: =F47/100*G47 -> 0 | I47: =H47+F47 -> 1.44
A48: 3 | B48: EGG | C48: 1 | D48: PCS | E48: ='Master Price list'!G207 -> 0.5 | F48: =E48*C48 -> 0.5 | G48: 0 | H48: =F48/100*G48 -> 0 | I48: =H48+F48 -> 0.5
A49: 4 | B49: VANILLA EXTRACT | C49: 0.01 | D49: KG | E49: ='Master Price list'!G121 -> 39.6 | F49: =E49*C49 -> 0.396 | G49: 0 | H49: =F49/100*G49 -> 0 | I49: =H49+F49 -> 0.396
A50: 5 | B50: BUTTER, MELTED | C50: 0.15 | D50: KG | E50: ='Master Price list'!G21 -> 39.2 | F50: =E50*C50 -> 5.88 | G50: 0 | H50: =F50/100*G50 -> 0 | I50: =H50+F50 -> 5.88
A51: 6 | B51: SUGAR, WHITE | C51: 0.02 | D51: KG | E51: ='Master Price list'!G120 -> 4.6 | F51: =E51*C51 -> 0.092 | G51: 0 | H51: =F51/100*G51 -> 0 | I51: =H51+F51 -> 0.092
...

Sheet Menu Item list
A1: ITEM NAME | B1: ITEM PRICE
A2: BIG BREAKFAST W/BACON | B2: ='Menu item calculator'!F12 -> 15.227749
A3: BIG BREAKFAST W/CHICKEN | B3: ='Menu item calculator'!F26 -> 15.227749
A4: BIG BREAKFAST W/PORK | B4: ='Menu item calculator'!F40 -> 15.227749
A5: BIG BREAKFAST W/BEEF | B5: ='Menu item calculator'!F54 -> 15.619249 | G5: 2 | H5: 5 items | I5: 0.7 | J5: =(80*I5)*G5 -> 112
A6: ALL DAY W/BACON | B6: ='Menu item calculator'!F68 -> 12.302455 | G6: 6 | H6: 5 items | I6: 0.2 | J6: =(80*I6)*G6 -> 96
A7: ALL DAY W/CHICKEN | B7: ='Menu item calculator'!F82 -> 12.302455 | G7: 20 | H7: 3 items | I7: 0.1 | J7: =(80*I7)*G7 -> 160
A8: ALL DAY W/PORK | B8: ='Menu item calculator'!F96 -> 12.302455 | I8: =SUM(I5:I7) -> 1
A9: ALL DAY W/BEEF | B9: ='Menu item calculator'!F110 -> 12.693955 | J9: =SUM(J5:J7) -> 368 | K9: goal is RM350
A10: CREPPES W/CARAMELIZED BANANA | B10: ='Menu item calculator'!F121 -> 3.7039399
A11: CREPPES W/LEMON & SUGAR | B11: ='Menu item calculator'!F133 -> 2.8514399
A12: CREPPES W/NUTELLA | B12: ='Menu item calculator'!F144 -> 4.2102046
A13: OMELETTE PLAIN | B13: ='Menu item calculator'!F156 -> 6.0332661
A14: OMELETTE W/SALMON 50GM | B14: ='Menu item calculator'!F169 -> 12.433266
A15: OMELETTE W/CHEESE & MUSHROOM | B15: ='Menu item calculator'!F183 -> 8.7232661
A16: EGGS BENEDICT W/BACON | B16: ='Menu item calculator'!F197 -> 10.626496
A17: EGGS MARLBOROUGH W/SALMON | B17: ='Menu item calculator'!F211 -> 13.598996
A18: TOAST W/BUTTER & JAM | B18: ='Menu item calculator'!F220 -> 0.28246867
A19: SWEET CORN PANCAKES W/BACON | B19: RECIPE MISSING
A20: MUESLI W/HONEY,YOGHURT,FRUIT | B20: ='Menu item calculator'!F245 -> 4.7135225
A21: PANCAKE BANANA | B21: ='Menu item calculator'!F255 -> 6.893627
A22: PORRIDGE W/HONEY & BANANA | B22: ='Menu item calculator'!F268 -> 3.5439749
A23: ASPARAGUS W/BACON | B23: ='Menu item calculator'!F279 -> 11.724653
A24: SCRAMBLED EGGS W/SALMON 50G | B24: ='Menu item calculator'!F291 -> 12.345573
A25: FRESH FRUIT SALAD W/YOGHURT | B25: ='Menu item calculator'!F298 -> 2.9467
A26: FRENCH TOAST W/BERRY COMPOTE | B26: ='Menu item calculator'!F309 -> 5.3527634
A27: FRENCH TOAST W/BANANA BACON | B27: ='Menu item calculator'!F320 -> 5.8647389
A28: FRENCH TOAST W/BACON & MAPLE | B28: ='Menu item calculator'!F331 -> 5.7092389
A29: FRENCH TOAST W/PEARS & BACON | B29: ='Menu item calculator'!F345 -> 7.9863889
A30: TOMATO W/ MUSHROOM ON TOAST | B30: ='Menu item calculator'!F360 -> 6.7422917
A31: BACON & EGG PIE | B31: ='Menu item calculator'!F378 -> 10.595723
A32: SCRAMBLED EGGS FETA W/SPINACH | B32: ='Menu item calculator'!F389 -> 6.4831278
A33: AVOCADO BACON ON TOAST | B33: ='Menu item calculator'!F402 -> 3.4825109
A34: AVOCADO HALOUMI CHEES ON TOAST | B34: ='Menu item calculator'!F415 -> 7.4961841
A35: AVOCADO ON TOAST W/ SALMON | B35: ='Menu item calculator'!F430 -> 8.1066261
A36: NASI GORENG | B36: ='Menu item calculator'!F447 -> 5.6296128
A37: OPEN BACON ROCKET SANDWICH | B37: ='Menu item calculator'!F459 -> 6.5508333
A38: OPEN BACON LETTUCE SANDWICH | B38: ='Menu item calculator'!F471 -> 6.0708333
A39: OPEN CHICKEN SANDWICH | B39: ='Menu item calculator'!F483 -> 3.6417156
A40: THAI CHICKEN SATAY | B40: ='Menu item calculator'!F494 -> 4.7674818
...

Sheet Menu item calculator
A1: BIG BREAKFAST W/BACON
A2: NO | B2: INGREDIENT | C2: QUANTITY | D2: UOM | E2: UNIT PRICE | F2: TOTAL
A4: 1 | B4: FRENCH VILLAGE | C4: 1 | D4: SERVING | E4: ='Master Price list'!G69/10 -> 0.066508333 | F4: =E4*C4 -> 0.066508333
A5: 2 | B5: BUTTER, SALTED | C5: 0.01 | D5: KG | E5: ='Master Price list'!G21 -> 39.2 | F5: =E5*C5 -> 0.392
A6: 3 | B6: HOUSE SALAD | C6: 1 | D6: SERVING | E6: ='Item list'!B31 -> 1.7691118 | F6: =E6*C6 -> 1.7691118
A7: 4 | B7: CHERRY TOMATO | C7: 0.002 | D7: KG | E7: ='Master Price list'!G169 -> 11.5 | F7: =E7*C7 -> 0.023
A8: 5 | B8: SAUTEED MUSHROOM | C8: 1 | D8: SERVING | E8: ='Item list calculator'!I23 -> 4.1504444 | F8: =E8*C8 -> 4.1504444
A9: 6 | B9: SCRAMBLED EGG | C9: 1 | D9: SERVING | E9: ='Item list'!B2 -> 3.6284444 | F9: =E9*C9 -> 3.6284444
A10: 7 | B10: HASHBROWN | C10: 1 | D10: SERVING | E10: ='Item list'!B30 -> 1.7707397 | F10: =E10*C10 -> 1.7707397
A11: 8 | B11: BACK BACON | C11: 0.075 | D11: KG | E11: ='Master Price list'!G7 -> 45.7 | F11: =E11*C11 -> 3.4275
D12: TOTAL | F12: =SUM(F4:F11) -> 15.227749
A15: BIG BREAKFAST W/CHICKEN
A16: NO | B16: INGREDIENT | C16: QUANTITY | D16: UOM | E16: UNIT PRICE | F16: TOTAL
A18: 1 | B18: FRENCH VILLAGE | C18: 1 | D18: SERVING | E18: ='Master Price list'!G69/10 -> 0.066508333 | F18: =E18*C18 -> 0.066508333
A19: 2 | B19: BUTTER, SALTED | C19: 0.01 | D19: KG | E19: ='Master Price list'!G21 -> 39.2 | F19: =E19*C19 -> 0.392
A20: 3 | B20: HOUSE SALAD | C20: 1 | D20: SERVING | E20: ='Item list'!B31 -> 1.7691118 | F20: =E20*C20 -> 1.7691118
A21: 4 | B21: CHERRY TOMATO | C21: 0.002 | D21: KG | E21: =E7 -> 11.5 | F21: =E21*C21 -> 0.023
A22: 5 | B22: SAUTEED MUSHROOM | C22: 1 | D22: SERVING | E22: =E8 -> 4.1504444 | F22: =E22*C22 -> 4.1504444
A23: 6 | B23: SCRAMBLED EGG | C23: 1 | D23: SERVING | E23: =E9 -> 3.6284444 | F23: =E23*C23 -> 3.6284444
A24: 7 | B24: HASHBROWN | C24: 1 | D24: SERVING | E24: =E10 -> 1.7707397 | F24: =E24*C24 -> 1.7707397
A25: 8 | B25: CHICKEN SAUSAGE | C25: 0.075 | D25: KG | E25: ='Master Price list'!G14 -> 45.7 | F25: =E25*C25 -> 3.4275
D26: TOTAL | F26: =SUM(F18:F25) -> 15.227749
A29: BIG BREAKFAST W/PORK
A30: NO | B30: INGREDIENT | C30: QUANTITY | D30: UOM | E30: UNIT PRICE | F30: TOTAL
A32: 1 | B32: FRENCH VILLAGE | C32: 1 | D32: SERVING | E32: =E18 -> 0.066508333 | F32: =E32*C32 -> 0.066508333
A33: 2 | B33: BUTTER, SALTED | C33: 0.01 | D33: KG | E33: =E19 -> 39.2 | F33: =E33*C33 -> 0.392
A34: 3 | B34: HOUSE SALAD | C34: 1 | D34: SERVING | E34: =E20 -> 1.7691118 | F34: =E34*C34 -> 1.7691118
A35: 4 | B35: CHERRY TOMATO | C35: 0.002 | D35: KG | E35: =E21 -> 11.5 | F35: =E35*C35 -> 0.023
A36: 5 | B36: SAUTEED MUSHROOM | C36: 1 | D36: SERVING | E36: =E22 -> 4.1504444 | F36: =E36*C36 -> 4.1504444
A37: 6 | B37: SCRAMBLED EGG | C37: 1 | D37: SERVING | E37: =E23 -> 3.6284444 | F37: =E37*C37 -> 3.6284444
A38: 7 | B38: HASHBROWN | C38: 1 | D38: SERVING | E38: =E24 -> 1.7707397 | F38: =E38*C38 -> 1.7707397
A39: 8 | B39: PORK SAUSAGE | C39: 0.075 | D39: KG | E39: ='Master Price list'!G11 -> 45.7 | F39: =E39*C39 -> 3.4275
D40: TOTAL | F40: =SUM(F32:F39) -> 15.227749
A43: BIG BREAKFAST W/BEEF
A44: NO | B44: INGREDIENT | C44: QUANTITY | D44: UOM | E44: UNIT PRICE | F44: TOTAL
A46: 1 | B46: FRENCH VILLAGE | C46: 1 | D46: SERVING | E46: =E32 -> 0.066508333 | F46: =E46*C46 -> 0.066508333
A47: 2 | B47: BUTTER, SALTED | C47: 0.01 | D47: KG | E47: =E33 -> 39.2 | F47: =E47*C47 -> 0.392
A48: 3 | B48: HOUSE SALAD | C48: 1 | D48: SERVING | E48: =E34 -> 1.7691118 | F48: =E48*C48 -> 1.7691118
A49: 4 | B49: CHERRY TOMATO | C49: 0.002 | D49: KG | E49: =E35 -> 11.5 | F49: =E49*C49 -> 0.023
A50: 5 | B50: SAUTEED MUSHROOM | C50: 1 | D50: SERVING | E50: =E36 -> 4.1504444 | F50: =E50*C50 -> 4.1504444
...

Sheet INGREDIENTS
B1: SUPLIER & ITEMS | C1: UNIT | D1: PRICE | E1: UNIT | F1: PRICE | H1: Monday Thunder Stock | I1: Min Home Stock | J1: Order Amount
B2: Thunder HOUSE Blend | N2: Blend %
B3: Indonesia Robusta | C3: kg | D3: =3430.7/120 -> 28.589167 | M3: =D3*N3 -> 7.1472917 | N3: 0.25
B4: Ethiopia | C4: kg | D4: 36.4 | M4: =D4*N4 -> 27.3 | N4: 0.75
B5: BLEND PRICE | E5: gm | F5: =M5/1000 -> 0.040526225 | M5: =(SUM(M3:M4))/0.85 -> 40.526225 | N5: KG price
B6: Thunder MAGIC Blend | N6: Blend %
B7: Rwanda | C7: kg | D7: 40 | M7: =D7*N7 -> 20 | N7: 0.5
B8: Ethiopia | C8: kg | D8: 36.4 | M8: =D8*N8 -> 18.2 | N8: 0.5
B9: BLEND PRICE | E9: gm | F9: =M9/1000 -> 0.044941176 | M9: =(SUM(M7:M8))/0.85 -> 44.941176 | N9: KG price
B10: Flacon Greens
B11: Brazil Roasted Beans | C11: kg | D11: 70 | E11: gm | F11: =D11/1000 -> 0.07
D12: 0 | F12: =D12/1000 -> 0
D13: 0 | F13: =D13/1000 -> 0
D14: 0 | F14: =D14/1000 -> 0
D15: 0 | F15: =D15/1000 -> 0
D16: 0 | F16: =D16/1000 -> 0
B18: OBTECH
B19: 12 oz double wall hot cups ( plain white) | C19: ctn | D19: 160 | E19: PCS | F19: =D19/500 -> 0.32
B20: Pla Sipper hot Cup Lids 12oz/16oz white | C20: ctn | D20: 220 | E20: PCS | F20: =D20/1000 -> 0.22
B21: 12 oz Plastic pet cup | C21: ctn | D21: 270 | E21: PCS | F21: =D21/1000 -> 0.27
B22: 12 oz Plastic cup lids | C22: ctn | D22: 230 | E22: PCS | F22: =D22/2000 -> 0.115
B23: 8OZ HOT CUP | C23: ctn | D23: 250 | E23: PCS | F23: =D23/1000 -> 0.25
B24: 8OZ HOT CUP LIDS | C24: ctn | D24: 220 | E24: PCS | F24: =D24/1000 -> 0.22
B25: satchel paper Bag - White | C25: ctn | D25: 270 | E25: PCS | F25: =D25/5000 -> 0.054
B26: 16 oz Plastic Pet cup | C26: ctn | D26: 290 | E26: PCS | F26: =D26/1000 -> 0.29
B27: 16 oz Plastic Pet lids Flate Lids | C27: ctn | D27: 150 | E27: PCS | F27: =D27/1000 -> 0.15
B28: Paper Straw | C28: Ctn | D28: 290 | E28: PCS | F28: =D28/5000 -> 0.058
B29: UGS
B30: 8oz Double wall Paper Cup white | C30: ctn | D30: 130 | F30: =D30/500 -> 0.26
B31: 12oz Double wall Paper cup White | C31: ctn
B32: 16OZ Tall Double Wall Paper Cup White | C32: ctn | D32: 190 | F32: =D32/500 -> 0.38
B33: 12oz 95mm Cleare ICED cup | C33: ctn | D33: 250 | F33: =D33/1000 -> 0.25
B34: Paper Straw White wrapped | C34: ctn | D34: 130 | F34: =D34/5000 -> 0.026
B35: 12oz/16oz ICED lids | C35: ctn | D35: 110 | F35: =D35/2000 -> 0.055
B37: AYC
B38: Farm fresh milk | C38: ctn/6btl/litter | D38: 14.26 | E38: ml | F38: =D38/1000 -> 0.01426
D39: 0 | F39: =D39/1000 -> 0
D40: 0 | F40: =D40/1000 -> 0
D41: 0 | F41: =D41/1000 -> 0
D42: 0 | F42: =D42/1000 -> 0
...

Sheet Christmas Drinks 
B3: Eggnog Batch
B5: Ingredients | C5: Quantity | D5: Unit | E5: Cost Price | F5: Total Price
B6: Oat Milk | C6: 1.5 | D6: L | E6: =INGREDIENTS!F196 -> 0.03 | F6: =E6*C6 -> 0.045
B7: Cashew Nut | C7: 300 | D7: gm | E7: =12.9/300 -> 0.043 | F7: =E7*C7 -> 12.9
B8: Staranis | C8: 15 | D8: gm | E8: =3.8/30 -> 0.12666667 | F8: =E8*C8 -> 1.9
B9: Cinamon | C9: 30 | D9: Gm | E9: =3.8/30 -> 0.12666667 | F9: =E9*C9 -> 3.8
B10: Maple Syrup | C10: 90 | D10: ML | E10: =14.1/90 -> 0.15666667 | F10: =E10*C10 -> 14.1
F14: =SUM(F6:F13) -> 32.745
B15: Total Production Yield | C15: 2000
B16: Cost Per gm /ml | C16: =F14/C15 -> 0.0163725
B19: AngelFrost
B21: Ingredients | C21: Quantity | D21: Unit | E21: Cost Price | F21: Total Price
B22: 12oz ICED Cup | C22: 1 | D22: pcs | E22: =INGREDIENTS!F21 -> 0.27 | F22: =E22*C22 -> 0.27
B23: 12oz ICED Lids | C23: 1 | D23: pcs | E23: =INGREDIENTS!F22 -> 0.115 | F23: =E23*C23 -> 0.115
B24: Straw | C24: 1 | D24: Pcs | E24: =INGREDIENTS!F28 -> 0.058 | F24: =E24*C24 -> 0.058
B25: Coconut Cream | C25: 30 | D25: ml | E25: =11.5/1000 -> 0.0115 | F25: =E25*C25 -> 0.345
B26: Blue Syrup | C26: 20 | D26: ml | E26: =69/1000 -> 0.069 | F26: =E26*C26 -> 1.38
B27: Sugar Syrup | C27: 10 | D27: ml | E27: =INGREDIENTS!F179 -> 0.0048 | F27: =E27*C27 -> 0.048
B28: Lemon Juice | C28: 10 | D28: ml | E28: =INGREDIENTS!F108 -> 0.0095 | F28: =E28*C28 -> 0.095
B29: Milk | C29: 90 | D29: ml | E29: =INGREDIENTS!F38 -> 0.01426 | F29: =E29*C29 -> 1.2834
F30: =SUM(F22:F29) -> 3.5944
B31: Selling Price | C31: 13
B32: Cost Price | C32: =F30+5% -> 3.6444 | D32: =C32/C31 -> 0.28033846
B35: Vegan Eggnog
B37: 12oz ICED Cup | C37: 1 | D37: pcs | E37: =INGREDIENTS!F21 -> 0.27 | F37: =E37*C37 -> 0.27
B38: 12oz ICED Lids | C38: 1 | D38: pcs | E38: =INGREDIENTS!F11 -> 0.07 | F38: =E38*C38 -> 0.07
B39: Straw | C39: 1 | D39: Pcs | E39: =INGREDIENTS!F28 -> 0.058 | F39: =E39*C39 -> 0.058
B40: Mixed Eggnog | C40: 180 | D40: ml | E40: =C16 -> 0.0163725 | F40: =E40*C40 -> 2.94705
F45: =SUM(F37:F44) -> 3.34505
B46: Selling Price | C46: 15
B47: Cost Price | C47: =F45+5% -> 3.39505 | D47: =C47/C46 -> 0.22633667

Sheet RAVE EVENT 
D2: Min Pax | E2: 250 | F2: =E2*$C$6 -> 788.62476
D3: Expected Pax | E3: 400 | F3: =E3*$C$6 -> 1261.7996
D4: Max Pax | E4: 550 | F4: =E4*$C$6 -> 1734.9745
B6: Average Profit (less 20%); | C6: =(AVERAGE(C22,C39,C57,C74,C92))*0.8 -> 3.154499 | D6: Total Hous: | E6: 5 | F6: =F3/E6 -> 252.35992
B8: EDFLOWER ICE TEA
B10: Ingredients | C10: Quantity | D10: Unit | E10: Cost Price | F10: Total Price
B11: ElderFlower | C11: 30 | D11: ml | E11: =INGREDIENTS!F201 -> 0.028378378 | F11: =E11*C11 -> 0.85135135
B12: Lemon Juice | C12: 10 | D12: Ml | E12: =INGREDIENTS!F108 -> 0.0095 | F12: =E12*C12 -> 0.095
B13: Black Tea | C13: 1 | D13: Pcs | E13: =INGREDIENTS!F187 -> 0.106 | F13: =E13*C13 -> 0.106
B14: Salt | C14: 0.5 | D14: Gm | E14: =INGREDIENTS!F133 -> 0.01 | F14: =E14*C14 -> 0.005
B15: House Syrup | C15: 5 | D15: ML | E15: =INGREDIENTS!F179 -> 0.0048 | F15: =E15*C15 -> 0.024
B16: 12 Oz ice Cup | C16: 1 | D16: Pcs | E16: =INGREDIENTS!F21 -> 0.27 | F16: =E16*C16 -> 0.27
B17: Ice Lids | C17: 1 | D17: Pcs | E17: =INGREDIENTS!F22 -> 0.115 | F17: =E17*C17 -> 0.115
B18: Straw | C18: 1 | D18: Pcs | E18: =INGREDIENTS!F28 -> 0.058 | F18: =E18*C18 -> 0.058
F19: =SUM(F11:F18) -> 1.5243514
B20: Selling Price | C20: 5.5
B21: Cost Price | C21: =F19+5% -> 1.5743514 | D21: =C21/C20 -> 0.2862457
B22: Profit | C22: =C20-C21 -> 3.9256486
B25: COCO ICEBREW
B27: Ingredients | C27: Quantity | D27: Unit | E27: Cost Price | F27: Total Price
B28: Cold Brew | C28: 90 | D28: ML | E28: ='KITCHEN Prep Cards'!C24 -> 0.0046 | F28: =E28*C28 -> 0.414
B29: Coconut Syrup | C29: 25 | D29: ML | E29: =INGREDIENTS!F198 -> 0.028378378 | F29: =E29*C29 -> 0.70945946
B30: Lemon Juice | C30: 15 | D30: ML | E30: =INGREDIENTS!F108 -> 0.0095 | F30: =E30*C30 -> 0.1425
B31: House Syrup | C31: 5 | D31: ML | E31: =INGREDIENTS!F179 -> 0.0048 | F31: =E31*C31 -> 0.024
B32: Salt | C32: 0.5 | D32: gm | E32: =INGREDIENTS!F133 -> 0.01 | F32: =E32*C32 -> 0.005
B33: 12 Oz ice Cup | C33: 1 | D33: Pcs | E33: =INGREDIENTS!F21 -> 0.27 | F33: =E33*C33 -> 0.27
B34: Ice Lids | C34: 1 | D34: Pcs | E34: =INGREDIENTS!F22 -> 0.115 | F34: =E34*C34 -> 0.115
B35: Straw | C35: 1 | D35: Pcs | E35: =INGREDIENTS!F28 -> 0.058 | F35: =E35*C35 -> 0.058
F36: =SUM(F28:F35) -> 1.7379595
B37: Selling Price | C37: 5.5
B38: Cost Price | C38: =F36+5% -> 1.7879595 | D38: =C38/C37 -> 0.32508354
B39: Profit | C39: =C37-C38 -> 3.7120405
B42: LEMONGRASS ICE TEA
B44: Ingredients | C44: Quantity | D44: Unit | E44: Cost Price | F44: Total Price
B45: Lemon Grass Syrup | C45: 25 | D45: ML | E45: =INGREDIENTS!F202 -> 0.028378378 | F45: =E45*C45 -> 0.70945946
B46: Lemon Juice | C46: 15 | D46: ML | E46: =INGREDIENTS!F108 -> 0.0095 | F46: =E46*C46 -> 0.1425
B47: Mint Leaf | C47: 1 | D47: gm | E47: =INGREDIENTS!F134 -> 0.0888 | F47: =E47*C47 -> 0.0888
B48: Black Tea ( 90 ml ) | C48: 1 | D48: pcs | E48: =INGREDIENTS!F187 -> 0.106 | F48: =E48*C48 -> 0.106
B49: Salt | C49: 0.5 | D49: gm | E49: =INGREDIENTS!F133 -> 0.01 | F49: =E49*C49 -> 0.005
B50: Asam Boi | C50: 3 | D50: gm | E50: =INGREDIENTS!F197 -> 0.018 | F50: =E50*C50 -> 0.054
...

Sheet NEW MENU COSTING 
B3: Pesto Chicken Pasta
B5: Ingredients | C5: Quantity | D5: Unit | E5: Cost Price | F5: Total Price
B6: Chicken Breast | C6: 50 | D6: gm | E6: =INGREDIENTS!F$120 -> 0.011 | F6: =Table1[[#This Row],[Cost Price ]]*Table1[[#This Row],[Quantity]] -> 0.55
B7: Sunflower Oil | C7: 15 | D7: ml | E7: =INGREDIENTS!F$131 -> 0.010571429 | F7: =Table1[[#This Row],[Cost Price ]]*Table1[[#This Row],[Quantity]] -> 0.15857143
B8: Parmesan Cheese | C8: 5 | D8: gm | E8: =INGREDIENTS!F$93 -> 0.07 | F8: =Table1[[#This Row],[Cost Price ]]*Table1[[#This Row],[Quantity]] -> 0.35
B9: Spaghethi | C9: 130 | D9: gm | E9: =INGREDIENTS!F$122 -> 0.012 | F9: =Table1[[#This Row],[Cost Price ]]*Table1[[#This Row],[Quantity]] -> 1.56
B10: Tomato | C10: 30 | D10: gm | E10: =INGREDIENTS!F117 -> 0.0045 | F10: =Table1[[#This Row],[Cost Price ]]*Table1[[#This Row],[Quantity]] -> 0.135
B11: Salt | C11: 1 | D11: gm | E11: =INGREDIENTS!F128 -> 0.019 | F11: =Table1[[#This Row],[Cost Price ]]*Table1[[#This Row],[Quantity]] -> 0.019
B12: Pesto Sauce | C12: 25 | D12: gm | E12: ='KITCHEN Prep Cards'!C50 -> 0.051098214 | F12: =Table1[[#This Row],[Cost Price ]]*Table1[[#This Row],[Quantity]] -> 1.2774554
B13: Pepper | C13: 1 | D13: gm | E13: =INGREDIENTS!F133 -> 0.01 | F13: =Table1[[#This Row],[Cost Price ]]*Table1[[#This Row],[Quantity]] -> 0.01
F18: =SUM(F6:F13) -> 4.0600268
B19: Selling Price | C19: 27
B20: Cost Price | C20: =F18+5% -> 4.1100268 | D20: =C20/C19 -> 0.15222321
B21: Profit | C21: =C19-C20 -> 22.889973
B24: Pesto Chicken Sandwich
B26: Ingredients | C26: Quantity | D26: Unit | E26: Cost Price | F26: Total Price
B27: Chicken Breast | C27: 90 | D27: gm | E27: =INGREDIENTS!F137 -> 0.018 | F27: =Table13[[#This Row],[Cost Price ]]*Table13[[#This Row],[Quantity]] -> 1.62
B28: Sunflower Oil | C28: 15 | D28: ml | E28: =INGREDIENTS!F131 -> 0.010571429 | F28: =Table13[[#This Row],[Cost Price ]]*Table13[[#This Row],[Quantity]] -> 0.15857143
B29: Parmesan Cheese | C29: 5 | D29: gm | E29: =INGREDIENTS!F93 -> 0.07 | F29: =Table13[[#This Row],[Cost Price ]]*Table13[[#This Row],[Quantity]] -> 0.35
B30: Tomato | C30: 50 | D30: gm | E30: =INGREDIENTS!F117 -> 0.0045 | F30: =Table13[[#This Row],[Cost Price ]]*Table13[[#This Row],[Quantity]] -> 0.225
B31: Foccacia Bread | C31: 1 | D31: pcs | E31: =INGREDIENTS!D81 -> 2 | F31: =Table13[[#This Row],[Cost Price ]]*Table13[[#This Row],[Quantity]] -> 2
B32: Salt | C32: 1 | D32: gm | E32: =INGREDIENTS!F133 -> 0.01 | F32: =Table13[[#This Row],[Cost Price ]]*Table13[[#This Row],[Quantity]] -> 0.01
B33: Pesto Sauce | C33: 30 | D33: gm | E33: ='KITCHEN Prep Cards'!C50 -> 0.051098214 | F33: =Table13[[#This Row],[Cost Price ]]*Table13[[#This Row],[Quantity]] -> 1.5329464
B34: Pepper | C34: 1 | D34: gm | E34: =INGREDIENTS!F158 -> 0.06 | F34: =Table13[[#This Row],[Cost Price ]]*Table13[[#This Row],[Quantity]] -> 0.06
B35: Bega Cheese | C35: 1 | D35: pcs | E35: =INGREDIENTS!F51 -> 0.41428571 | F35: =Table13[[#This Row],[Cost Price ]]*Table13[[#This Row],[Quantity]] -> 0.41428571
F38: =SUM(F27:F36) -> 6.3708036
B39: Selling Price | C39: 25 | F39: =Table13[[#This Row],[Cost Price ]]*Table13[[#This Row],[Quantity]] -> 0
B40: Cost Price | C40: =F38+5% -> 6.4208036 | D40: =C40/C39 -> 0.25683214 | F40: =Table13[[#This Row],[Cost Price ]]*Table13[[#This Row],[Quantity]] -> 0
B41: Profit | C41: =C39-C40 -> 18.579196 | F41: =Table13[[#This Row],[Cost Price ]]*Table13[[#This Row],[Quantity]] -> 0
B44: Red Creamy Chicken Pasta
B46: Ingredients | C46: Quantity | D46: Unit | E46: Cost Price | F46: Total Price
B47: Whipping Cream | C47: 50 | D47: ml | E47: =INGREDIENTS!$F90 -> 0.026 | F47: =Table134[[#This Row],[Cost Price ]]*Table134[[#This Row],[Quantity]] -> 1.3
B48: Conchiglie Pasta | C48: 130 | D48: gm | E48: =INGREDIENTS!$F95 -> 0.016 | F48: =Table134[[#This Row],[Cost Price ]]*Table134[[#This Row],[Quantity]] -> 2.08
B49: Galice | C49: 5 | D49: gm | E49: =INGREDIENTS!$F123 -> 0.01 | F49: =Table134[[#This Row],[Cost Price ]]*Table134[[#This Row],[Quantity]] -> 0.05
B50: Sunflower Oil | C50: 5 | D50: ml | E50: =INGREDIENTS!F$131 -> 0.010571429 | F50: =Table134[[#This Row],[Cost Price ]]*Table134[[#This Row],[Quantity]] -> 0.052857143
B51: Parmesan Cheese | C51: 10 | D51: gm | E51: =INGREDIENTS!F$93 -> 0.07 | F51: =Table134[[#This Row],[Cost Price ]]*Table134[[#This Row],[Quantity]] -> 0.7
B52: Tamto Pest | C52: 20 | D52: gm | E52: =INGREDIENTS!F88 -> 0.0188 | F52: =Table134[[#This Row],[Cost Price ]]*Table134[[#This Row],[Quantity]] -> 0.376
B53: Half Slice of bread | C53: 0.5 | D53: pcs | E53: =INGREDIENTS!$F77 -> 2.2857143 | F53: =Table134[[#This Row],[Cost Price ]]*Table134[[#This Row],[Quantity]] -> 1.1428571
B54: Chicken Breast | C54: 130 | D54: gm | E54: =INGREDIENTS!$F137 -> 0.018 | F54: =Table134[[#This Row],[Cost Price ]]*Table134[[#This Row],[Quantity]] -> 2.34
B55: Salt | C55: 1 | D55: gm | E55: =INGREDIENTS!F$133 -> 0.01 | F55: =Table134[[#This Row],[Cost Price ]]*Table134[[#This Row],[Quantity]] -> 0.01
...

Sheet DRINK Prep Cards
B3: CHCOLATE SYRUP BATCH
B5: Ingredients | C5: Quantity | D5: Unit | E5: Cost Price | F5: Total Price
B6: Chocolate Powder | C6: 200 | D6: gm | E6: =50/1000 -> 0.05 | F6: =E6*C6 -> 10
B7: Cocoa Powder | C7: 300 | D7: gm | E7: =INGREDIENTS!F169 -> 0.07 | F7: =E7*C7 -> 21
B8: White Sugar | C8: 150 | D8: gm | E8: =INGREDIENTS!F164 -> 0.0048 | F8: =E8*C8 -> 0.72
B9: Water | C9: 1000 | D9: ml | E9: 0 | F9: =E9*C9 -> 0
B11: Total Production Yield | C11: =SUM(C6:C10) -> 1650 | F11: =SUM(F6:F10) -> 31.72
B12: Cost Per gm | C12: =F11/C11 -> 0.019224242
B15: COLD BREW BATCH
B17: Ingredients | C17: Quantity | D17: Unit | E17: Cost Price | F17: Total Price
B18: Coffee Ground | C18: 230 | D18: gm | E18: =INGREDIENTS!F11 -> 0.07 | F18: =E18*C18 -> 16.1
B19: Filter Water | C19: 3500 | D19: gm | E19: 0 | F19: =E19*C19 -> 0
B23: Total Production Yield | C23: 3500 | F23: =SUM(F18:F22) -> 16.1
B24: Production Per Ml | C24: =F23/C23 -> 0.0046

Sheet HOT Drinks 
B2: 6oz | N2: 12oz | T2: 16oz
B5: Thunder HOUSE Blend | N5: Thunder HOUSE Blend | T5: Thunder HOUSE Blend
B7: Ingredients | C7: Quantity | D7: Unit | E7: Cost Price | F7: Total Price | N7: Ingredients | O7: Quantity | P7: Unit | Q7: Cost Price | R7: Total Price | T7: Ingredients | U7: Quantity | V7: Unit | W7: Cost Price | X7: Total Price
B8: Coffee | C8: =16+(16*0.025) -> 16.4 | D8: gm | E8: =INGREDIENTS!$F$5 -> 0.040526225 | F8: =(E8*C8)/2 -> 0.33231505 | N8: Coffee | O8: =16+(16*0.025) -> 16.4 | P8: gm | Q8: =INGREDIENTS!$F$5 -> 0.040526225 | R8: =Q8*O8 -> 0.6646301 | T8: Coffee | U8: =16+(16*0.025) -> 16.4 | V8: gm | W8: =INGREDIENTS!$F$5 -> 0.040526225 | X8: =W8*U8 -> 0.6646301
B9: Farm Fresh Milk | C9: 110 | D9: ML | E9: =INGREDIENTS!$F$38 -> 0.01426 | F9: =E9*C9 -> 1.5686 | N9: Farm Fresh Milk | O9: 215 | P9: ML | Q9: =INGREDIENTS!$F$38 -> 0.01426 | R9: =Q9*O9 -> 3.0659 | T9: Farm Fresh Milk | U9: 250 | V9: ML | W9: =INGREDIENTS!$F$38 -> 0.01426 | X9: =W9*U9 -> 3.565
B10: 6oz Hot Cup | C10: 1 | D10: pcs | E10: =INGREDIENTS!F211 -> 0.076 | F10: =E10*C10 -> 0.076 | N10: 12oz Hot Cup | O10: 1 | P10: pcs | Q10: =INGREDIENTS!$F$19 -> 0.32 | R10: =Q10*O10 -> 0.32 | T10: 16oz Hot Cup | U10: 1 | V10: pcs | W10: =INGREDIENTS!F26 -> 0.29 | X10: =W10*U10 -> 0.29
N11: 12oz hot Cup Lids | O11: 1 | P11: pcs | Q11: =INGREDIENTS!$F$20 -> 0.22 | R11: =Q11*O11 -> 0.22 | T11: 16oz hot Cup Lids | U11: 1 | V11: pcs | W11: =INGREDIENTS!F27 -> 0.15 | X11: =W11*U11 -> 0.15
F13: =SUM(F8:F12) -> 1.976915 | R13: =SUM(R8:R12) -> 4.2705301 | X13: =SUM(X8:X12) -> 4.6696301
B14: Selling Price | C14: 6 | N14: Selling Price | O14: 8.5 | T14: Selling Price | U14: 10.5
B15: Cost Price | C15: =F13+5% -> 2.026915 | D15: =C15/C14 -> 0.33781917 | N15: Cost Price | O15: =R13+5% -> 4.3205301 | P15: =O15/O14 -> 0.50829766 | T15: Cost Price | U15: =X13+5% -> 4.7196301 | V15: =U15/U14 -> 0.44948858
B16: Profit | C16: =C14-C15 -> 3.973085 | N16: Profit | O16: =O14-O15 -> 4.1794699 | T16: Profit | U16: =U14-U15 -> 5.7803699
B18: 6oz | H18: 8oz | N18: 12oz | T18: 16oz
B21: Traditional Chai | H21: Thunder MAGIC Blend | N21: Thunder MAGIC Blend | T21: Thunder MAGIC Blend
B23: Ingredients | C23: Quantity | D23: Unit | E23: Cost Price | F23: Total Price | H23: Ingredients | I23: Quantity | J23: Unit | K23: Cost Price | L23: Total Price | N23: Ingredients | O23: Quantity | P23: Unit | Q23: Cost Price | R23: Total Price | T23: Ingredients | U23: Quantity | V23: Unit | W23: Cost Price | X23: Total Price
B24: Fresh Milk | C24: 200 | D24: Ml | E24: =INGREDIENTS!$F$38 -> 0.01426 | F24: =E24*C24 -> 2.852 | H24: Coffee | I24: =16+(16*0.025) -> 16.4 | J24: gm | K24: =INGREDIENTS!$F$9 -> 0.044941176 | L24: =(K24*I24)/2 -> 0.36851765 | N24: Coffee | O24: =16+(16*0.025) -> 16.4 | P24: gm | Q24: =INGREDIENTS!$F$9 -> 0.044941176 | R24: =Q24*O24 -> 0.73703529 | T24: Coffee | U24: =16+(16*0.025) -> 16.4 | V24: gm | W24: =INGREDIENTS!$F$9 -> 0.044941176 | X24: =W24*U24 -> 0.73703529
B25: BOH Tea | C25: 2 | D25: Gm | E25: =INGREDIENTS!$F$284 -> 0.0296 | F25: =E25*C25 -> 0.0592 | H25: Farm Fresh Milk | I25: 180 | J25: ML | K25: =INGREDIENTS!$F$38 -> 0.01426 | L25: =K25*I25 -> 2.5668 | N25: Farm Fresh Milk | O25: 215 | P25: ML | Q25: =INGREDIENTS!$F$38 -> 0.01426 | R25: =Q25*O25 -> 3.0659 | T25: Farm Fresh Milk | U25: 225 | V25: ML | W25: =INGREDIENTS!$F$38 -> 0.01426 | X25: =W25*U25 -> 3.2085
B26: White Sugar | C26: 20 | D26: Gm | E26: =INGREDIENTS!$F$164 -> 0.0048 | F26: =E26*C26 -> 0.096 | H26: 8oz Hot Cup | I26: 1 | J26: pcs | K26: =INGREDIENTS!$F$23 -> 0.25 | L26: =K26*I26 -> 0.25 | N26: 12oz Hot Cup | O26: 1 | P26: pcs | Q26: =INGREDIENTS!$F$19 -> 0.32 | R26: =Q26*O26 -> 0.32 | T26: 16oz Hot Cup | U26: 1 | V26: pcs | W26: =INGREDIENTS!F207 -> 0.38 | X26: =W26*U26 -> 0.38
B27: Cardamom | C27: 2 | D27: gm | E27: =INGREDIENTS!$F$282 -> 0.17 | F27: =E27*C27 -> 0.34 | H27: 8oz hot Cup Lids | I27: 1 | J27: pcs | K27: =INGREDIENTS!$F$24 -> 0.22 | L27: =K27*I27 -> 0.22 | N27: 12oz hot Cup Lids | O27: 1 | P27: pcs | Q27: =INGREDIENTS!$F$20 -> 0.22 | R27: =Q27*O27 -> 0.22 | T27: 16oz hot Cup Lids | U27: 1 | V27: pcs | W27: =INGREDIENTS!$F$20 -> 0.22 | X27: =W27*U27 -> 0.22
B28: Young Ginger | C28: 1 | D28: gm | E28: =INGREDIENTS!$F$283 -> 0.03 | F28: =E28*C28 -> 0.03
B29: Gloves | C29: 1 | D29: gm | E29: =INGREDIENTS!F283 -> 0.03 | F29: =E29*C29 -> 0.03
B30: Water | C30: 150 | D30: ML | E30: 0 | F30: =E30*C30 -> 0 | L30: =SUM(L24:L28) -> 3.4053176 | R30: =SUM(R24:R28) -> 4.3429353 | X30: =SUM(X24:X28) -> 4.5455353
B31: 6oz Take Away Paper Cups | C31: 1 | D31: Pcs | E31: =INGREDIENTS!$F$211 -> 0.076 | F31: =E31*C31 -> 0.076
B33: Selling Price | C33: 4 | F33: =SUM(F24:F31) -> 3.4832 | H33: Selling Price | I33: 8.5 | N33: Selling Price | O33: 10 | T33: Selling Price | U33: 12
B34: Cost Price | C34: =F33/2 -> 1.7416 | D34: =C34/C33 -> 0.4354 | H34: Cost Price | I34: =L30+5% -> 3.4553176 | J34: =I34/I33 -> 0.40650796 | N34: Cost Price | O34: =R30+5% -> 4.3929353 | P34: =O34/O33 -> 0.43929353 | T34: Cost Price | U34: =X30+5% -> 4.5955353 | V34: =U34/U33 -> 0.38296127
B35: Profit | C35: =C33-C34 -> 2.2584 | H35: Profit | I35: =I33-I34 -> 5.0446824 | N35: Profit | O35: =O33-O34 -> 5.6070647 | T35: Profit | U35: =U33-U34 -> 7.4044647
H37: 8oz | N37: 12Oz | T37: 16Oz
H40: Falcon Greens - White Coffee Hot Without Flavor 8oz | N40: Falcon Greens - White Coffee Hot Without Flavor 120z | T40: Falcon Greens - White Coffee Hot Without Flavor 160z
H42: Ingredients | I42: Quantity | J42: Unit | K42: Cost Price | L42: Total Price | N42: Ingredients | O42: Quantity | P42: Unit | Q42: Cost Price | R42: Total Price | T42: Ingredients | U42: Quantity | V42: Unit | W42: Cost Price | X42: Total Price
H43: Coffee | I43: =16+(16*0.025) -> 16.4 | J43: gm | K43: =INGREDIENTS!$F$11 -> 0.07 | L43: =K43*I43 -> 1.148 | N43: Coffee | O43: =16+(16*0.025) -> 16.4 | P43: gm | Q43: =INGREDIENTS!F11 -> 0.07 | R43: =Q43*O43 -> 1.148 | T43: Coffee | U43: =16+(16*0.025) -> 16.4 | V43: gm | W43: =INGREDIENTS!F11 -> 0.07 | X43: =W43*U43 -> 1.148
H44: Farm Fresh Milk | I44: 205 | J44: ML | K44: =INGREDIENTS!$F$38 -> 0.01426 | L44: =K44*I44 -> 2.9233 | N44: Farm Fresh Milk | O44: 215 | P44: ML | Q44: =INGREDIENTS!$F$38 -> 0.01426 | R44: =Q44*O44 -> 3.0659 | T44: Farm Fresh Milk | U44: 225 | V44: ML | W44: =INGREDIENTS!$F$38 -> 0.01426 | X44: =W44*U44 -> 3.2085
H45: 8oz Hot Cup | I45: 1 | J45: pcs | K45: =INGREDIENTS!$F$23 -> 0.25 | L45: =K45*I45 -> 0.25 | N45: 12oz Hot Cup | O45: 1 | P45: pcs | Q45: =INGREDIENTS!$F$19 -> 0.32 | R45: =Q45*O45 -> 0.32 | T45: 16oz Hot Cup | U45: 1 | V45: pcs | W45: =INGREDIENTS!F207 -> 0.38 | X45: =W45*U45 -> 0.38
H46: 8oz hot Cup Lids | I46: 1 | J46: pcs | K46: =INGREDIENTS!$F$24 -> 0.22 | L46: =K46*I46 -> 0.22 | N46: 12oz hot Cup Lids | O46: 1 | P46: pcs | Q46: =INGREDIENTS!$F$20 -> 0.22 | R46: =Q46*O46 -> 0.22 | T46: 16oz hot Cup Lids | U46: 1 | V46: pcs | W46: =INGREDIENTS!$F$20 -> 0.22 | X46: =W46*U46 -> 0.22
L48: =SUM(L43:L47) -> 4.5413 | R48: =SUM(R43:R47) -> 4.7539 | X48: =SUM(X43:X47) -> 4.9565
H49: Selling Price | I49: 8 | N49: Selling Price | O49: 8.5 | T49: Selling Price | U49: 11
H50: Cost Price | I50: =L48+5% -> 4.5913 | J50: =I50/I49 -> 0.5739125 | N50: Cost Price | O50: =R48+5% -> 4.8039 | P50: =O50/O49 -> 0.56516471 | T50: Cost Price | U50: =X48+5% -> 5.0065 | V50: =U50/U49 -> 0.45513636
H51: Profit | I51: =I49-I50 -> 3.4087 | N51: Profit | O51: =O49-O50 -> 3.6961 | T51: Profit | U51: =U49-U50 -> 5.9935
H53: Gesha 8oz | N53: 12Oz | T53: 16Oz
H56: Falcon Greens - White Coffee Hot Without Flavor 8oz | N56: Falcon Greens - White Coffee Hot Without Flavor 120z | T56: Falcon Greens - White Coffee Hot Without Flavor 160z
H58: Ingredients | I58: Quantity | J58: Unit | K58: Cost Price | L58: Total Price | N58: Ingredients | O58: Quantity | P58: Unit | Q58: Cost Price | R58: Total Price | T58: Ingredients | U58: Quantity | V58: Unit | W58: Cost Price | X58: Total Price
H59: Coffee | I59: =16+(18*0.025) -> 16.45 | J59: gm | K59: =INGREDIENTS!$F$31 -> 0 | L59: =K59*I59 -> 0 | N59: Coffee | O59: =16+(18*0.025) -> 16.45 | P59: gm | Q59: =INGREDIENTS!F47 -> 0 | R59: =Q59*O59 -> 0 | T59: Coffee | U59: =16+(18*0.025) -> 16.45 | V59: gm | W59: =INGREDIENTS!F47 -> 0 | X59: =W59*U59 -> 0
...

Sheet ICED Drinks 
B2: 12Oz | H2: 16Oz
B5: Falcon Greens - White Coffee Hot Without Flavor 120z | H5: Falcon Greens - White Coffee Hot Without Flavor 160z
B7: Ingredients | C7: Quantity | D7: Unit | E7: Cost Price | F7: Total Price | H7: Ingredients | I7: Quantity | J7: Unit | K7: Cost Price | L7: Total Price
B8: Coffee | C8: =16+(18*0.025) -> 16.45 | D8: gm | E8: =INGREDIENTS!F11 -> 0.07 | F8: =E8*C8 -> 1.1515 | H8: Coffee | I8: =16+(18*0.025) -> 16.45 | J8: gm | K8: =INGREDIENTS!F11 -> 0.07 | L8: =K8*I8 -> 1.1515
B9: Farm Fresh Milk | C9: 215 | D9: ML | E9: =INGREDIENTS!F38 -> 0.01426 | F9: =E9*C9 -> 3.0659 | H9: Farm Fresh Milk | I9: 225 | J9: ML | K9: =INGREDIENTS!F38 -> 0.01426 | L9: =K9*I9 -> 3.2085
B10: 12oz ICED Cup | C10: 1 | D10: pcs | E10: =INGREDIENTS!F21 -> 0.27 | F10: =E10*C10 -> 0.27 | H10: 16oz ICED Cup | I10: 1 | J10: pcs | K10: =INGREDIENTS!F26 -> 0.29 | L10: =K10*I10 -> 0.29
B11: 12oz ICED Cup Lids | C11: 1 | D11: pcs | E11: =INGREDIENTS!F22 -> 0.115 | F11: =E11*C11 -> 0.115 | H11: 16oz ICED Cup Lids | I11: 1 | J11: pcs | K11: =INGREDIENTS!F27 -> 0.15 | L11: =K11*I11 -> 0.15
B12: Straw | C12: 1 | D12: pcs | E12: =INGREDIENTS!F28 -> 0.058 | F12: =E12*C12 -> 0.058 | H12: Straw | I12: 1 | J12: pcs | K12: =INGREDIENTS!F28 -> 0.058 | L12: =K12*I12 -> 0.058
F13: =SUM(F8:F12) -> 4.6604 | L13: =SUM(L8:L12) -> 4.858
B14: Selling Price | C14: 8.5 | H14: Selling Price | I14: 11
B15: Cost Price | C15: =F13+5% -> 4.7104 | D15: =C15/C14 -> 0.55416471 | H15: Cost Price | I15: =L13+5% -> 4.908 | J15: =I15/I14 -> 0.44618182
B16: Profit | C16: =C14-C15 -> 3.7896 | H16: Profit | I16: =I14-I15 -> 6.092
B18: Falcon Greens - White Coffee With Flavor | H18: Falcon Greens - White Coffee With Flavor
B20: Ingredients | C20: Quantity | D20: Unit | E20: Cost Price | F20: Total Price | H20: Ingredients | I20: Quantity | J20: Unit | K20: Cost Price | L20: Total Price
B21: Coffee | C21: =16+(18*0.025) -> 16.45 | D21: gm | E21: =INGREDIENTS!F11 -> 0.07 | F21: =E21*C21 -> 1.1515 | H21: Coffee | I21: =16+(18*0.025) -> 16.45 | J21: gm | K21: =INGREDIENTS!$F$49 -> 0.0093 | L21: =K21*I21 -> 0.152985
B22: Farm Fresh Milk | C22: 215 | D22: ML | E22: =INGREDIENTS!$F$38 -> 0.01426 | F22: =E22*C22 -> 3.0659 | H22: Farm Fresh Milk | I22: 225 | J22: ML | K22: =INGREDIENTS!$F$38 -> 0.01426 | L22: =K22*I22 -> 3.2085
B23: 12oz ICED Cup | C23: 1 | D23: pcs | E23: =INGREDIENTS!F21 -> 0.27 | F23: =E23*C23 -> 0.27 | H23: 16oz ICED Cup | I23: 1 | J23: pcs | K23: =INGREDIENTS!F26 -> 0.29 | L23: =K23*I23 -> 0.29
B24: 12oz ICED Cup Lids | C24: 1 | D24: pcs | E24: =INGREDIENTS!F22 -> 0.115 | F24: =E24*C24 -> 0.115 | H24: 16oz ICED Cup Lids | I24: 1 | J24: pcs | K24: =INGREDIENTS!F21 -> 0.27 | L24: =K24*I24 -> 0.27
B25: Add On Any flavor | C25: 10 | D25: ml | E25: =INGREDIENTS!$F$58 -> 0.0695 | F25: =E25*C25 -> 0.695 | H25: Add On Any flavor | I25: 10 | J25: ml | K25: =INGREDIENTS!$F$58 -> 0.0695 | L25: =K25*I25 -> 0.695
B26: Straw | C26: 1 | D26: pcs | E26: =INGREDIENTS!F28 -> 0.058 | F26: =E26*C26 -> 0.058 | H26: Straw | I26: 1 | J26: pcs | K26: =INGREDIENTS!F28 -> 0.058 | L26: =K26*I26 -> 0.058
F30: =SUM(F21:F29) -> 5.3554 | L30: =SUM(L21:L29) -> 4.674485
B31: Selling Price | C31: 9.5 | H31: Selling Price | I31: 12
B32: Cost Price | C32: =F30+5% -> 5.4054 | D32: =C32/C31 -> 0.56898947 | H32: Cost Price | I32: =L30+5% -> 4.724485 | J32: =I32/I31 -> 0.39370708
B33: Profit | C33: =C31-C32 -> 4.0946 | H33: Profit | I33: =I31-I32 -> 7.275515
B36: Falcon Greens - White Coffee Mocha | H36: Falcon Greens - White Coffee Mocha
B38: Ingredients | C38: Quantity | D38: Unit | E38: Cost Price | F38: Total Price | H38: Ingredients | I38: Quantity | J38: Unit | K38: Cost Price | L38: Total Price
B39: Coffee | C39: =8+(18*0.025) -> 8.45 | D39: gm | E39: =INGREDIENTS!F11 -> 0.07 | F39: =E39*C39 -> 0.5915 | H39: Coffee | I39: =8+(18*0.025) -> 8.45 | J39: gm | K39: =INGREDIENTS!F11 -> 0.07 | L39: =K39*I39 -> 0.5915
B40: Farm Fresh Milk | C40: 215 | D40: ML | E40: =INGREDIENTS!F38 -> 0.01426 | F40: =E40*C40 -> 3.0659 | H40: Farm Fresh Milk | I40: 225 | J40: ML | K40: =INGREDIENTS!$F$38 -> 0.01426 | L40: =K40*I40 -> 3.2085
B41: 12oz ICED Cup | C41: 1 | D41: pcs | E41: =INGREDIENTS!F26 -> 0.29 | F41: =E41*C41 -> 0.29 | H41: 16oz ICED Cup | I41: 1 | J41: pcs | K41: =INGREDIENTS!F195 -> 0.1 | L41: =K41*I41 -> 0.1
B42: 12oz ICED Cup Lids | C42: 1 | D42: pcs | E42: =INGREDIENTS!F22 -> 0.115 | F42: =E42*C42 -> 0.115 | H42: 16oz ICED Cup Lids | I42: 1 | J42: pcs | K42: =INGREDIENTS!F20 -> 0.22 | L42: =K42*I42 -> 0.22
B43: Cocolate Syrup | C43: 15 | D43: gm | E43: ='KITCHEN Prep Cards'!C12 -> 0.019224242 | F43: =E43*C43 -> 0.28836364 | H43: Cocolate Syrup | I43: 15 | J43: gm | K43: ='KITCHEN Prep Cards'!C12 -> 0.019224242 | L43: =K43*I43 -> 0.28836364
B44: Straw | C44: 1 | D44: pcs | E44: =INGREDIENTS!F28 -> 0.058 | F44: =E44*C44 -> 0.058 | H44: Straw | I44: 1 | J44: pcs | K44: =INGREDIENTS!F28 -> 0.058 | L44: =K44*I44 -> 0.058
F48: =SUM(F39:F47) -> 4.4087636 | L48: =SUM(L39:L47) -> 4.4663636
B49: Selling Price | C49: 8.5 | H49: Selling Price | I49: 11
B50: Cost Price | C50: =F48+5% -> 4.4587636 | D50: =C50/C49 -> 0.52456043 | H50: Cost Price | I50: =L48+5% -> 4.5163636 | J50: =I50/I49 -> 0.41057851
B51: Profit | C51: =C49-C50 -> 4.0412364 | H51: Profit | I51: =I49-I50 -> 6.4836364
B54: ICED Chocolate | H54: ICED Chocolate
B56: Ingredients | C56: Quantity | D56: Unit | E56: Cost Price | F56: Total Price | H56: Ingredients | I56: Quantity | J56: Unit | K56: Cost Price | L56: Total Price
B57: Farm Fresh Milk | C57: 215 | D57: ML | E57: =INGREDIENTS!F38 -> 0.01426 | F57: =E57*C57 -> 3.0659 | H57: Farm Fresh Milk | I57: 225 | J57: ML | K57: =INGREDIENTS!F38 -> 0.01426 | L57: =K57*I57 -> 3.2085
B58: 12oz ICED Cup | C58: 1 | D58: pcs | E58: =INGREDIENTS!F21 -> 0.27 | F58: =E58*C58 -> 0.27 | H58: 16oz ICED Cup | I58: 1 | J58: pcs | K58: =INGREDIENTS!F26 -> 0.29 | L58: =K58*I58 -> 0.29
...

Sheet KITCHEN Prep Cards
B3: CHCOLATE SYRUP BATCH
B5: Ingredients | C5: Quantity | D5: Unit | E5: Cost Price | F5: Total Price
B6: Chocolate Powder | C6: 200 | D6: gm | E6: =50/1000 -> 0.05 | F6: =E6*C6 -> 10
B7: Cocoa Powder | C7: 300 | D7: gm | E7: =INGREDIENTS!F169 -> 0.07 | F7: =E7*C7 -> 21
B8: White Sugar | C8: 150 | D8: gm | E8: =INGREDIENTS!F164 -> 0.0048 | F8: =E8*C8 -> 0.72
B9: Water | C9: 1000 | D9: ml | E9: 0 | F9: =E9*C9 -> 0
B11: Total Production Yield | C11: =SUM(C6:C10) -> 1650 | F11: =SUM(F6:F10) -> 31.72
B12: Cost Per gm | C12: =F11/C11 -> 0.019224242
B15: COLD BREW BATCH
B17: Ingredients | C17: Quantity | D17: Unit | E17: Cost Price | F17: Total Price
B18: Coffee Ground | C18: 230 | D18: gm | E18: =INGREDIENTS!F11 -> 0.07 | F18: =E18*C18 -> 16.1
B19: Filter Water | C19: 3500 | D19: gm | E19: 0 | F19: =E19*C19 -> 0
B23: Total Production Yield | C23: 3500 | F23: =SUM(F18:F22) -> 16.1
B24: Production Per Ml | C24: =F23/C23 -> 0.0046
B27: Chilli Mayo Sauce
B29: Ingredients | C29: Quantity | D29: Unit | E29: Cost Price | F29: Total Price
B30: Mayonese | C30: 800 | D30: gm | E30: =INGREDIENTS!F109 -> 0.02 | F30: =E30*C30 -> 16
B31: Chilli Sauce | C31: 200 | D31: gm | E31: =INGREDIENTS!F138 -> 0.013819444 | F31: =E31*C31 -> 2.7638889
B32: Chilli Flakes | C32: 30 | D32: gm | E32: =INGREDIENTS!F124 -> 0.0048 | F32: =E32*C32 -> 0.144
B33: Sunflower Oil | C33: 10 | D33: ml | E33: =INGREDIENTS!F131 -> 0.010571429 | F33: =E33*C33 -> 0.10571429
B35: Total Production Yield | C35: 1000 | F35: =SUM(F30:F34) -> 19.013603
B36: Production Per Gm | C36: =F35/C35 -> 0.019013603
B39: Pesto Sauce
B41: Ingredients | C41: Quantity | D41: Unit | E41: Cost Price | F41: Total Price
B42: Parmesan cheese | C42: 30 | D42: gm | E42: =INGREDIENTS!F93 -> 0.07 | F42: =E42*C42 -> 2.1
B43: Almond | C43: 120 | D43: gm | E43: =INGREDIENTS!F158 -> 0.06 | F43: =E43*C43 -> 7.2
B44: Basil Leaf | C44: 100 | D44: gm | E44: =INGREDIENTS!F136 -> 0.086 | F44: =E44*C44 -> 8.6
B45: Garlic | C45: 30 | D45: gm | E45: =INGREDIENTS!F123 -> 0.01 | F45: =E45*C45 -> 0.3
B46: Salt | C46: 3 | D46: gm | E46: =INGREDIENTS!F133 -> 0.01 | F46: =E46*C46 -> 0.03
B47: Sunflower Oil | C47: 200 | D47: ml | E47: =INGREDIENTS!F131 -> 0.010571429 | F47: =E47*C47 -> 2.1142857
B48: Lemon Juice | C48: 10 | D48: ml | E48: =INGREDIENTS!F108 -> 0.0095 | F48: =E48*C48 -> 0.095
B49: Total Production Yield | C49: 400 | F49: =SUM(F42:F48) -> 20.439286
B50: Production Per Gm | C50: =F49/C49 -> 0.051098214
B53: Tomato Sauce
B55: Ingredients | C55: Quantity | D55: Unit | E55: Cost Price | F55: Total Price
B56: Fresh Tomato | C56: 250 | D56: gm | E56: =INGREDIENTS!F117 -> 0.0045 | F56: =E56*C56 -> 1.125
B57: Tomato Pest | C57: 125 | D57: gm | E57: =INGREDIENTS!F88 -> 0.0188 | F57: =E57*C57 -> 2.35
B58: Red Onion | C58: 120 | D58: gm | E58: =INGREDIENTS!F110 -> 0.0035 | F58: =E58*C58 -> 0.42
B59: Garlic | C59: 30 | D59: gm | E59: =INGREDIENTS!F123 -> 0.01 | F59: =E59*C59 -> 0.3
B60: Salt | C60: 10 | D60: gm | E60: =INGREDIENTS!F133 -> 0.01 | F60: =E60*C60 -> 0.1
...

Sheet SERVE Cards
B3: Cheese Toastie (white)
B5: Ingredients | C5: Quantity | D5: Unit | E5: Cost Price | F5: Total Price
B6: White Bread | C6: 1 | D6: portion | E6: =INGREDIENTS!$F$288 -> 0.62857143 | F6: =E6*C6 -> 0.62857143
B7: Cheese | C7: 1 | D7: slice | E7: =INGREDIENTS!$F$51 -> 0.41428571 | F7: =E7*C7 -> 0.41428571
B8: Palm Oil | F8: =E8*C8 -> 0
B9: Packaging | C9: 1 | E9: 0.25 | F9: =E9*C9 -> 0.25
F10: =E10*C10 -> 0
F11: =E11*C11 -> 0
F12: =E12*C12 -> 0
F13: =E13*C13 -> 0
F14: =E14*C14 -> 0
F15: =SUM(F6:F14) -> 1.2928571
B16: Selling Price | C16: 5.9
B17: Cost Price | C17: =F15 -> 1.2928571 | D17: =C17/C16 -> 0.21912833
B18: Profit | C18: =C16-C17 -> 4.6071429
B21: Tomato/Cheese Toastie (white)
B23: Ingredients | C23: Quantity | D23: Unit | E23: Cost Price | F23: Total Price
B24: White Bread | C24: 1 | D24: portion | E24: =INGREDIENTS!$F$288 -> 0.62857143 | F24: =E24*C24 -> 0.62857143
B25: Cheese | C25: 1 | D25: slice | E25: =INGREDIENTS!$F$51 -> 0.41428571 | F25: =E25*C25 -> 0.41428571
B26: Tomato | C26: 50 | D26: gram | E26: =INGREDIENTS!$F$117 -> 0.0045 | F26: =E26*C26 -> 0.225
B27: Palm Oil | F27: =E27*C27 -> 0
F28: =E28*C28 -> 0
B29: Packaging | C29: 1 | E29: 0.25 | F29: =E29*C29 -> 0.25
F30: =E30*C30 -> 0
F31: =E31*C31 -> 0
F32: =E32*C32 -> 0
F33: =SUM(F24:F32) -> 1.5178571
B34: Selling Price | C34: 6.9
B35: Cost Price | C35: =F33 -> 1.5178571 | D35: =C35/C34 -> 0.2199793
B36: Profit | C36: =C34-C35 -> 5.3821429
B39: Ham/Cheese Toastie (white)
B41: Ingredients | C41: Quantity | D41: Unit | E41: Cost Price | F41: Total Price
B42: White Bread | C42: 1 | D42: portion | E42: =INGREDIENTS!$F$288 -> 0.62857143 | F42: =E42*C42 -> 0.62857143
B43: Cheese | C43: 1 | D43: slice | E43: =INGREDIENTS!$F$51 -> 0.41428571 | F43: =E43*C43 -> 0.41428571
